<?xml version="1.0"?>
<robot name="joint_motion_probe" xmlns:xacro="http://www.ros.org/wiki/xacro">
  <xacro:arg name="controllers_file" default=""/>

  <link name="world"/>
  <link name="base_link">
    <visual>
      <geometry><box size="0.2 0.2 0.2"/></geometry>
    </visual>
    <collision>
      <geometry><box size="0.2 0.2 0.2"/></geometry>
    </collision>
    <inertial>
      <mass value="1.0"/>
      <inertia ixx="0.01" ixy="0" ixz="0" iyy="0.01" iyz="0" izz="0.01"/>
    </inertial>
  </link>
  <link name="slider_link">
    <visual>
      <geometry><box size="0.1 0.1 0.1"/></geometry>
    </visual>
    <collision>
      <geometry><box size="0.1 0.1 0.1"/></geometry>
    </collision>
    <inertial>
      <mass value="0.25"/>
      <inertia ixx="0.001" ixy="0" ixz="0" iyy="0.001" iyz="0" izz="0.001"/>
    </inertial>
  </link>

  <joint name="world_joint" type="fixed">
    <parent link="world"/>
    <child link="base_link"/>
  </joint>
  <joint name="slider_joint" type="prismatic">
    <parent link="base_link"/>
    <child link="slider_link"/>
    <axis xyz="1 0 0"/>
    <limit lower="-0.5" upper="0.5" effort="20" velocity="1"/>
  </joint>

  <ros2_control name="GazeboSimSystem" type="system">
    <hardware>
      <plugin>gz_ros2_control/GazeboSimSystem</plugin>
    </hardware>
    <joint name="slider_joint">
      <command_interface name="position">
        <param name="min">-0.5</param>
        <param name="max">0.5</param>
      </command_interface>
      <state_interface name="position"/>
      <state_interface name="velocity"/>
    </joint>
  </ros2_control>

  <gazebo>
    <plugin filename="libgz_ros2_control-system.so" name="gz_ros2_control::GazeboSimROS2ControlPlugin">
      <parameters>$(arg controllers_file)</parameters>
    </plugin>
  </gazebo>
</robot>
